Workbook

Sheet Spend Export
A1: Business Partner Company Name | B1: Branch Id | C1: Main Category | D1: Sub Category | E1: Spend | F1: E-invoicing | G1: PO coverage | H1: Spend Under Control Coverage | I1: Count of Invoice Receipts | J1: Actual Invoice Payment Time Average (Invoice amount weighted) | K1: Invoice Payment Period Average (Invoice amount weighted) | L1: Business Partner Payment Terms Id | M1: SSC Policy Signed | N1: Supplier Missing Data
A2: Presto Oy | B2: 607555 | C2: IPPE - Personnel | D2: IPPE06 - Training & people development | E2: 37788.89 | I2: 67 | J2: 23.575455 | K2: 15.980053 | L2: STOP_N45 | M2: Yes | N2: No
A3: Edward Lynx AB | B3: 404521 | C3: IPPE - Personnel | D3: IPPE06 - Training & people development | E3: 692085 | I3: 44 | J3: 77.293244 | K3: 57.992502 | L3: STOP_N60 | M3: Yes | N3: No
A4: Hope Consulting Oy | B4: 389324 | C4: IPPE - Personnel | D4: IPPE06 - Training & people development | E4: 38500 | I4: 43 | J4: 29.890909 | K4: 14 | L4: STOP_N60 | M4: Yes | N4: No
A5: Sähköinfo Oy | B5: 604917 | C5: IPPE - Personnel | D5: IPPE06 - Training & people development | E5: 24830.14 | G5: 0.025 | H5: 0.042287317 | I5: 40 | J5: 24.526368 | K5: 17.103567 | L5: STOP_N45 | M5: No | N5: No
A6: Suomen Ensiapukoulutus Oy | B6: 332750 | C6: IPPE - Personnel | D6: IPPE06 - Training & people development | E6: 6838.19 | I6: 39 | J6: 29.872836 | K6: 25.732555 | L6: STOP_N14 | M6: No | N6: No
A7: AEL-Amiedu Oy | B7: 634973 | C7: IPPE - Personnel | D7: IPPE06 - Training & people development | E7: 53171.15 | I7: 24 | J7: 57.415873 | K7: 55.768382 | L7: STOP_N45 | M7: No | N7: No
A8: Apprix Oy | B8: 239755 | C8: IPPE - Personnel | D8: IPPE06 - Training & people development | E8: 16135 | I8: 20 | J8: 45.560378 | K8: 45 | L8: STOP_N45 | M8: No | N8: Yes
A9: Psykologipalvelut Hippu Pintilä | B9: 635240 | C9: IPPE - Personnel | D9: IPPE06 - Training & people development | E9: 26682.13 | I9: 19 | J9: 59.468497 | K9: 60 | L9: STOP_N60 | M9: Yes | N9: No
A10: Resilio Oy | B10: 407540 | C10: IPPE - Personnel | D10: IPPE06 - Training & people development | E10: 56523.34 | I10: 15 | J10: 24.355071 | K10: 3.9275811 | L10: STOP_N45 | M10: Yes | N10: Yes
A11: Jyväskylän Ammattikorkeakoulu | B11: 201515 | C11: IPPE - Personnel | D11: IPPE06 - Training & people development | E11: 53685.65 | G11: 0.071428571 | H11: 0.023986857 | I11: 14 | J11: 45.38641 | K11: 35.14694 | L11: STOP_N30 | M11: No | N11: Yes
A12: Sinkkonen Consulting Oy | B12: 349102 | C12: IPPE - Personnel | D12: IPPE06 - Training & people development | E12: 37360 | I12: 14 | J12: 25.55166 | K12: 24.273822 | L12: STOP_N45 | M12: No | N12: Yes
A13: Abitata | B13: 382766 | C13: IPPE - Personnel | D13: IPPE06 - Training & people development | E13: 10751.26 | I13: 13 | J13: 68.164944 | K13: 29.732124 | L13: STOP_N30 | M13: Yes | N13: Yes
A14: Bitville Oy | B14: 400676 | C14: IPPE - Personnel | D14: IPPE06 - Training & people development | E14: 58512 | I14: 13 | J14: 135.53199 | K14: 165.73175 | L14: STOP_N60 | M14: Yes | N14: No
A15: Finn-Tarkastus Oy | B15: 639705 | C15: IPPE - Personnel | D15: IPPE06 - Training & people development | E15: 19549.56 | G15: 0.15384615 | H15: 0.40561527 | I15: 13 | J15: 50.451247 | K15: 53.915771 | L15: STOP_N45 | M15: No | N15: No
A16: Helsingin Kamari Oy | B16: 509013 | C16: IPPE - Personnel | D16: IPPE06 - Training & people development | E16: 31866 | I16: 13 | J16: 39.680262 | K16: 25.155353 | L16: STOP_N45 | M16: No | N16: Yes
A17: IMD-International Institute for Managem. Develop. | B17: 383390 | C17: IPPE - Personnel | D17: IPPE06 - Training & people development | E17: 1524625.8 | I17: 13 | J17: 62.971378 | K17: 60 | L17: STOP_N60 | M17: No | N17: Yes
A18: Soutwestern Consulting LTD | B18: 656486 | C18: IPPE - Personnel | D18: IPPE06 - Training & people development | E18: 7325 | I18: 12 | J18: 19.112628 | K18: 17.767918 | L18: STOP_N60 | M18: Yes | N18: No
A19: Aalto University Executive Education Oy | B19: 615149 | C19: IPPE - Personnel | D19: IPPE06 - Training & people development | E19: 220586.65 | I19: 11 | J19: 42.552561 | K19: 40.944002 | L19: STOP_N45 | M19: Yes | N19: No
A20: Punainen Risti Ensiapu Oy | B20: 408310 | C20: IPPE - Personnel | D20: IPPE06 - Training & people development | E20: 2361 | I20: 11 | J20: 26.824227 | K20: 29.35197 | L20: STOP_N14 | M20: No | N20: Yes
A21: Tulityö ja työturvallisuuskoulutus Kalle Hankomäki Oy | B21: 380921 | C21: IPPE - Personnel | D21: IPPE06 - Training & people development | E21: 1401.9 | I21: 11 | J21: 29.726799 | K21: 14 | L21: STOP_N45 | M21: No | N21: Yes
A22: AS3 Finland Oy | B22: 403389 | C22: IPPE - Personnel | D22: IPPE06 - Training & people development | E22: 28297.19 | I22: 10 | J22: 56.38003 | K22: 52.759062 | L22: STOP_N60 | M22: Yes | N22: No
A23: Koolituskorraldus OÜ | B23: 641406 | C23: IPPE - Personnel | D23: IPPE06 - Training & people development | E23: 1791.99 | I23: 10 | J23: 19.333272 | K23: 7.9285654 | L23: STOP_N14 | M23: Yes | N23: No
A24: Hyvinvoinnin Suurlähettiläät Oy | B24: 635292 | C24: IPPE - Personnel | D24: IPPE06 - Training & people development | E24: 48739.9 | G24: 0.77777778 | H24: 0.71891612 | I24: 9 | J24: 64.68351 | K24: 49.938531 | L24: STOP_N60 | M24: No | N24: Yes
A25: BCFO Business Coaching Finland Oy | B25: 374821 | C25: IPPE - Personnel | D25: IPPE06 - Training & people development | E25: 52639 | I25: 8 | J25: 24.175706 | K25: 11.8723 | L25: STOP_N45 | M25: No | N25: Yes
A26: Oy Speakers Forum Finland Ab | B26: 331659 | C26: IPPE - Personnel | D26: IPPE06 - Training & people development | E26: 11146 | I26: 8 | J26: 27.523955 | K26: 22.182487 | L26: STOP_N45 | M26: No | N26: Yes
A27: Pohto Oy | B27: 602473 | C27: IPPE - Personnel | D27: IPPE06 - Training & people development | E27: 11712.9 | I27: 8 | J27: 42.462127 | K27: 43.351689 | L27: STOP_N45 | M27: No | N27: Yes
A28: Imaction | B28: 646544 | C28: IPPE - Personnel | D28: IPPE06 - Training & people development | E28: 39100 | I28: 7 | J28: 60.768542 | K28: 61.276215 | L28: STOP_N60 | M28: Yes | N28: No
A29: Presto Oy | B29: 511007 | C29: IPPE - Personnel | D29: IPPE06 - Training & people development | E29: 3927.33 | I29: 7 | J29: 22.392893 | K29: 14 | L29: STOP_N45 | M29: Yes | N29: No
A30: Rokmind Oy | B30: 647801 | C30: IPPE - Personnel | D30: IPPE06 - Training & people development | E30: 7000 | I30: 7 | J30: 60.46 | K30: 60 | L30: STOP_N60 | M30: Yes | N30: No
A31: Tampere Business Campus TBC ry | B31: 224445 | C31: IPPE - Personnel | D31: IPPE06 - Training & people development | E31: 21295 | I31: 7 | J31: 32.705095 | K31: 30 | L31: STOP_N30 | M31: No | N31: No
A32: EF Language Learning Solutions AG | B32: 310141 | C32: IPPE - Personnel | D32: IPPE06 - Training & people development | E32: 4947.42 | I32: 6 | J32: 151.60276 | K32: 60 | L32: STOP_N60 | M32: Yes | N32: No
A33: International Institute for Learning Finland Oy | B33: 295648 | C33: IPPE - Personnel | D33: IPPE06 - Training & people development | E33: 31615.03 | I33: 6 | J33: 63.156131 | K33: 60.734212 | L33: STOP_N60 | M33: No | N33: No
A34: Peili Consulting Oy | B34: 386353 | C34: IPPE - Personnel | D34: IPPE06 - Training & people development | E34: 17679.65 | I34: 6 | J34: 61.62838 | K34: 60 | L34: STOP_N60 | M34: Yes | N34: No
A35: HAK Nova Oy | B35: 630977 | C35: IPPE - Personnel | D35: IPPE06 - Training & people development | E35: 4980 | I35: 5 | J35: 34.620482 | K35: 36.174699 | L35: STOP_N60 | M35: Yes | N35: No
A36: Innotiimi Oy | B36: 604023 | C36: IPPE - Personnel | D36: IPPE06 - Training & people development | E36: 45434.45 | I36: 5 | J36: 56.610278 | K36: 56.877998 | L36: STOP_N45 | M36: Yes | N36: Yes
A37: Kajaanin Ammattikorkeakoulu Oy | B37: 386089 | C37: IPPE - Personnel | D37: IPPE06 - Training & people development | E37: 10447.8 | G37: 0.8 | H37: 0.78942935 | I37: 5 | J37: 50.351021 | K37: 51.135502 | L37: STOP_N45 | M37: Yes | N37: No
A38: Tina Sammi Oy | B38: 633539 | C38: IPPE - Personnel | D38: IPPE06 - Training & people development | E38: 3050 | I38: 5 | J38: 26.880952 | K38: 17.619048 | L38: STOP_N14 | M38: No | N38: No
A39: Catling Oy | B39: 663141 | C39: IPPE - Personnel | D39: IPPE06 - Training & people development | E39: 10000 | I39: 4 | J39: 39.9 | K39: 14 | L39: STOP_N30 | M39: Yes | N39: No
A40: Elina Lillstrang Oy | B40: 637008 | C40: IPPE - Personnel | D40: IPPE06 - Training & people development | E40: 22243.72 | I40: 4 | J40: 19.073375 | K40: 14 | L40: STOP_N60 | M40: Yes | N40: No
...

Sheet Supplierdata with FI spend
A1: Corporation | B1: Company | C1: Branch | D1: City (Street Address) | E1: Country/Region (Street Address) | F1: e-Mail | G1: Supplier Status | H1: Corporation Category | I1: Created | J1: Created By | K1: Company ID | L1: DUNS Code | M1: ValmetID | N1: Finland spend? | O1: Own ID | P1: Company VAT number | Q1: Preferred Supplier | R1: Purchase orders last three years | S1: Invoices last three years | T1: Supplier Categories | U1: Supplier Main Category | V1: Supplier Main Contact | W1: Supplier Main Contact eMail | X1: Terms Of Payment | Y1: Valmet Supplier Code of Conduct signed | Z1: Supplier sustainability policy signed | AA1: Valmet Supplier Manager | AB1: PAP Supplier Manager | AC1: P&E Supplier Manager | AD1: SER Supplier Manager | AE1: AS Supplier Manager | AF1: FC Supplier Manager | AG1: Buyer | AH1: Category Manager | AI1: Latest Approval | AJ1: Is supplier engaged to Valmet climate program? | AK1: MillID
A2: Capgemini Group | B2: Capgemini Finland Oy | C2: Capgemini Finland Oy | D2: HELSINKI | E2: Finland | G2: Active | H2: C3 | I2: 43489.408 | J2: Järvenpää Anssi | K2: 289334 | M2: 628390 | N2: =VLOOKUP(M2,'Spend Export'!$B:$E,4,FALSE) -> #N/A | P2: FI16281425 | Q2: X | R2: Yes | S2: Yes | T2: Indirect procurement iPRO, Office IT, Application management, IT consulting;Indirect procurement iPRO, Office IT, Application management, IT consulting, Other IT | U2: Indirect procurement iPRO, Office IT, Application management, IT consulting | V2: Aripirala Srikanth | W2: aripirala.srikanth@capgemini.com | X2: Net 45 days | Z2: X | AA2: Liukkonen Marko;Tapiola Mika;INACTIVE Länsimies Jukka;Jurvanen Juho | AI2: 2023-06-28 1001 - Infor LN (COF) (Valmet), Indirect procurement iPRO, Office IT, Application management, IT consulting (Main category) accepted by Tapiola Mika | AK2: 628390
A3: Know IT | B3: KnowIt Solutions Oy | C3: KnowIt Solutions Oy | D3: TAMPERE | E3: Finland | G3: Active | H3: C3 | I3: 44509.531 | J3: INACTIVE Kauppinen Ville | K3: 302922 | M3: 646437 | N3: =VLOOKUP(M3,'Spend Export'!$B:$E,4,FALSE) -> #N/A | P3: FI30945961 | R3: Yes | S3: Yes | T3: Indirect procurement iPRO, Office IT, Application management, IT consulting;Services, ICT engineering, ICT engineering | U3: Indirect procurement iPRO, Office IT, Application management, IT consulting | V3: Myllyoja Janne | W3: janne.myllyoja@knowit.fi | X3: Net 60 days | Y3: X | Z3: X | AA3: Burmeister Jari;Liukkonen Marko;Tapiola Mika | AE3: Pasanen Hannu | AG3: Kuukkanen Markus;INACTIVE Nopanen Atte | AI3: 2025-07-02 TC_SAP_FPER_PORG_OAFP - Valmet Tissue Conv. S.p.A LUCCA (PAP), Indirect procurement iPRO, Office IT proposed by Pollastrini Raffaello | AK3: 646437
B4: twoday oy | C4: twoday oy | D4: HELSINKI | E4: Finland | G4: Active | I4: 42403.682 | K4: 237016 | M4: 392337 | N4: =VLOOKUP(M4,'Spend Export'!$B:$E,4,FALSE) -> #N/A | P4: FI19880693 | Q4: X | R4: Yes | S4: Yes | T4: Indirect procurement iPRO, Office IT, IT consulting;Indirect procurement iPRO, Professional services;Services, R&D engineering;Services, R&D engineering, R&D engineering | U4: Indirect procurement iPRO, Office IT, IT consulting | V4: Dudley Patrick | W4: patrck.dudley@twoday.com | X4: Net 30 days | Z4: X | AA4: Tapiola Mika;Liukkonen Marko | AE4: Pasanen Hannu | AG4: Luhanko Tuomo;Borel Xavier | AI4: 2023-09-12 1001 - Infor LN (AS), Services, R&D engineering, R&D engineering accepted by Kiema Miika | AK4: 322503
B5: Midagon Oy | C5: Midagon Oy | D5: ESPOO | E5: Finland | F5: office@midagon.com | G5: Active | I5: 42361.524 | K5: 236586 | M5: 391845 | N5: =VLOOKUP(M5,'Spend Export'!$B:$E,4,FALSE) -> #N/A | P5: FI20582343 | R5: No | S5: Yes | T5: Indirect procurement iPRO, Office IT, IT consulting;Indirect procurement iPRO, Professional services, Business consulting | U5: Indirect procurement iPRO, Office IT, IT consulting | V5: Viitasalo Jussi | W5: jussi.viitasalo@midagon.com | X5: Net 30 days | Y5: X | AA5: Snedsböl Truls;Liukkonen Marko | AI5: 2025-03-27 Basware - Basware purchasing (Valmet), Indirect procurement iPRO, Professional services, Business consulting accepted by Snedsböl Truls | AK5: 391845
B6: Wipro Limited | C6: Wipro Limited | D6: BANGALORE | E6: India | G6: Active | I6: 42790.42 | K6: 144192 | M6: 404438 | N6: =VLOOKUP(M6,'Spend Export'!$B:$E,4,FALSE) -> #N/A | Q6: X | R6: No | S6: Yes | T6: Indirect procurement iPRO, Office IT, IT consulting | U6: Indirect procurement iPRO, Office IT, IT consulting | V6: Auvray Samuel | W6: samuel.auvray@wipro.com | X6: Net 45 days | Z6: X | AA6: Tapiola Mika;INACTIVE Länsimies Jukka;Liukkonen Marko | AK6: 404438
A7: Deloitte | B7: Deloitte Oy | C7: Deloitte Oy | D7: HELSINKI | E7: Finland | G7: Active | H7: C3 | I7: 38483.505 | K7: 80590 | M7: 210085 | N7: =VLOOKUP(M7,'Spend Export'!$B:$E,4,FALSE) -> 1915873.6 | P7: FI09897715 | R7: Yes | S7: Yes | T7: Indirect procurement iPRO, Professional services, Business consulting | U7: Indirect procurement iPRO, Professional services, Business consulting | V7: Huttu Essi | W7: Essi.Huttu@deloitte.fi | X7: Net 60 days | Z7: X | AG7: INACTIVE Ajo Marja-Liisa | AH7: Snedsböl Truls | AI7: 2025-05-29 1001 - Infor LN (COF) (Valmet), Indirect procurement iPRO, Professional services, Business consulting accepted by Snedsböl Truls | AK7: 210085
B8: Snowflake Computing Netherlands B.V. | C8: Snowflake Computing Netherlands B.V. | D8: AMSTERDAM | E8: Netherlands | G8: Active | I8: 44421.618 | J8: Toropainen Anita | K8: 301945 | M8: 644776 | N8: =VLOOKUP(M8,'Spend Export'!$B:$E,4,FALSE) -> #N/A | P8: NL859338083B01 | R8: Yes | S8: Yes | T8: Indirect procurement iPRO, Office IT, IT consulting | U8: Indirect procurement iPRO, Office IT, IT consulting | V8: Viitala Janne | W8: janne.viitala@snowflake.com | X8: Net 45 days | Z8: X | AI8: 2021-09-08 1001 - Infor LN (PAP), Indirect procurement iPRO, Office IT, IT consulting (Main category) accepted by Tapiola Mika | AK8: 644776
B9: IMD-International Institute for Managem. Develop. | C9: IMD-International Institute for Managem. Develop. | D9: LAUSANNE | E9: Switzerland | G9: Active | I9: 41967.514 | K9: 228311 | M9: 383390 | N9: =VLOOKUP(M9,'Spend Export'!$B:$E,4,FALSE) -> 1524625.8 | P9: CHE-106.448.807 MWST | Q9: X | R9: No | S9: Yes | T9: Indirect procurement iPRO, Personnel, Training & people development | U9: Indirect procurement iPRO, Personnel, Training & people development | X9: Net 60 days | AH9: Korpela Tuija | AK9: 383390
A10: Biisoni | B10: Biisoni Oy | C10: Biisoni Oy | D10: HELSINKI | E10: Finland | F10: info@biisoni.fi | G10: Active | H10: C3 | I10: 40864.475 | K10: 194030 | L10: 539784962 | M10: 344325 | N10: =VLOOKUP(M10,'Spend Export'!$B:$E,4,FALSE) -> 1459890.1 | P10: FI20480777 | Q10: X | R10: No | S10: Yes | T10: Indirect procurement iPRO, Personnel, Leased workforce | U10: Indirect procurement iPRO, Personnel, Leased workforce | V10: Illi Jukka | W10: jukka.illi@biisoni.fi | X10: Net 60 days | Y10: X | Z10: X | AH10: Korpela Tuija | AI10: 2025-02-04 FC - Infor M3 (FC) (FC), Valmet FC Finland Oy 310, Indirect procurement iPRO, Personnel, Leased workforce accepted by Korpela Tuija | AK10: 344325
A11: Dennemeyer | B11: Dennemeyer & Co. Sarl | C11: Dennemeyer & Co. Sarl | D11: HOWALD | E11: Luxembourg | G11: Active | H11: C3 | I11: 37918.593 | K11: 13858 | L11: 400450011 | M11: 606692 | N11: =VLOOKUP(M11,'Spend Export'!$B:$E,4,FALSE) -> 1439973.5 | P11: LU12748436 | R11: No | S11: Yes | T11: Indirect procurement iPRO, Professional services, Patent services | U11: Indirect procurement iPRO, Professional services, Patent services | V11: Fleming Carlene | W11: cfleming@dennemeyer.com | X11: Net 45 days | AK11: 606692
B12: TEec Oy | C12: TEec Oy | D12: JYVÄSKYLÄ | E12: Finland | F12: esa.kivijarvi@teec.fi | G12: Active | I12: 41564.311 | K12: 223187 | M12: 377128 | N12: =VLOOKUP(M12,'Spend Export'!$B:$E,4,FALSE) -> #N/A | P12: FI25773106 | R12: Yes | S12: Yes | T12: Indirect procurement iPRO, Office IT, IT consulting;Services, Mechanical engineering | U12: Indirect procurement iPRO, Office IT, IT consulting | V12: Kivijärvi Esa | W12: esa.kivijarvi@teec.fi | X12: Net 45 days | Z12: X | AA12: Liukkonen Marko;Tapiola Mika | AK12: 377128
B13: Sofigate Oy | C13: Sofigate Oy | D13: ESPOO | E13: Finland | G13: Active | I13: 39399.683 | K13: 116240 | M13: 252501 | N13: =VLOOKUP(M13,'Spend Export'!$B:$E,4,FALSE) -> #N/A | P13: FI19694727 | R13: No | S13: Yes | T13: Indirect procurement iPRO, Office IT, IT consulting | U13: Indirect procurement iPRO, Office IT, IT consulting | V13: Hyppänen Sakari | W13: sakari.hyppanen@sofigate.com | X13: Net 45 days | Y13: X | Z13: X | AA13: Tapiola Mika;Liukkonen Marko;INACTIVE Impersine Christopher | AK13: 252501
B14: Basware Oy | C14: Basware Oy | D14: ESPOO | E14: Finland | G14: Active | I14: 37918.569 | K14: 10822 | L14: 401717137 | M14: 616567 | N14: =VLOOKUP(M14,'Spend Export'!$B:$E,4,FALSE) -> #N/A | P14: FI05925424 | Q14: X | R14: Yes | S14: Yes | T14: Indirect procurement iPRO, Office IT, Application management;Indirect procurement iPRO, Office IT, Application management, IT consulting | U14: Indirect procurement iPRO, Office IT, Application management, IT consulting | V14: Tuomi Jaakko | W14: Jaakko.Tuomi@basware.com | X14: Net 30 days | Z14: X | AA14: Liukkonen Marko;Tapiola Mika | AI14: 2024-12-19 Basware - Basware purchasing (Valmet), Indirect procurement iPRO, Office IT, Application management accepted by Tapiola Mika | AK14: 616567
B15: BearingPoint Finland Oy | C15: BearingPoint Finland Oy | D15: HELSINKI | E15: Finland | G15: Active | I15: 38092.591 | K15: 58113 | M15: 175449 | N15: =VLOOKUP(M15,'Spend Export'!$B:$E,4,FALSE) -> 1359869 | P15: FI17496321 | R15: No | S15: Yes | T15: Indirect procurement iPRO, Professional services, Business consulting | U15: Indirect procurement iPRO, Professional services, Business consulting | V15: Hietanen Tomi | W15: tomi.hietanen@bearingpoint.com | X15: Net 45 days | Y15: X | AA15: INACTIVE Järvinen Janne;INACTIVE Markkanen Jaakko | AK15: 175449
B16: Crayon Oy | C16: Crayon Oy | D16: HELSINKI | E16: Finland | G16: Active | I16: 40304.365 | K16: 152723 | M16: 296632 | N16: =VLOOKUP(M16,'Spend Export'!$B:$E,4,FALSE) -> #N/A | P16: FI20960543 | R16: Yes | S16: Yes | T16: Indirect procurement iPRO, Office IT, Software licenses, IT consulting | U16: Indirect procurement iPRO, Office IT, Software licenses, IT consulting | V16: Johansson Kim | W16: kim.johnsson@crayon.com | X16: Net 30 days | Y16: X | Z16: X | AA16: Vasquez Francisco;Nurmi Riikka;Tapiola Mika;Liukkonen Marko | AI16: 2021-06-01 1001 - Infor LN (COF) (Valmet), Indirect procurement iPRO, Office IT, Software licenses, IT consulting (Main category) accepted by Liukkonen Marko | AK16: 296632
B17: Asianajotoimisto White & Case Oy | C17: Asianajotoimisto White & Case Oy | D17: HELSINKI | E17: Finland | G17: Active | I17: 37928.567 | K17: 37767 | M17: 160710 | N17: =VLOOKUP(M17,'Spend Export'!$B:$E,4,FALSE) -> 1272191.5 | P17: FI09078699 | R17: No | S17: Yes | T17: Indirect procurement iPRO, Professional services, Legal services | U17: Indirect procurement iPRO, Professional services, Legal services | V17: Pesonen Sevi | W17: s.pesonen@whitecase.com | X17: Net 60 days | Z17: X | AH17: INACTIVE Lavonen Antti | AI17: 2021-04-20 1001 - Infor LN (PAP), Indirect procurement iPRO, Professional services, Legal services (Main category) accepted by Mäkelä Henri | AK17: 160710
A18: Adecco Group AG | B18: Adecco Finland Oy | C18: Adecco Finland Oy | D18: VANTAA | E18: Finland | F18: adecco@adecco.fi | G18: Active | H18: C3 | I18: 39948.548 | K18: 137126 | L18: 651501934 | M18: 278118 | N18: =VLOOKUP(M18,'Spend Export'!$B:$E,4,FALSE) -> 1271566.2 | P18: FI10424640 | Q18: X | R18: Yes | S18: Yes | T18: Indirect procurement iPRO, Personnel, Leased workforce | U18: Indirect procurement iPRO, Personnel, Leased workforce | V18: Hänninen Henri | W18: henri.hanninen@adecco.fi | X18: Net 60 days | Y18: X | Z18: X | AE18: Tamminen Jari | AH18: Korpela Tuija | AI18: 2024-12-19 Workday - Workday Leased workforce (Valmet), Indirect procurement iPRO, Personnel, Leased workforce accepted by Korpela Tuija | AK18: 278118
B19: ServiceMax Inc. | C19: ServiceMax Inc. | D19: PLEASANTON | E19: United States | G19: Active | I19: 43703.581 | J19: INACTIVE Uusitalo Jukka | K19: 291503 | M19: 631492 | N19: =VLOOKUP(M19,'Spend Export'!$B:$E,4,FALSE) -> #N/A | Q19: X | R19: No | S19: Yes | T19: Indirect procurement iPRO, Office IT, Software licenses, Application management, IT consulting | U19: Indirect procurement iPRO, Office IT, Software licenses, Application management, IT consulting | V19: Rogers Glyn | W19: glyn.rogers@servicemax.com | X19: Net 45 days | Z19: X | AA19: Tapiola Mika;Liukkonen Marko | AI19: 2019-08-28 1001 - Infor LN (COF) (Valmet), Indirect procurement iPRO, Office IT, Software licenses, Application management, IT consulting (Main category) accepted by Tapiola Mika | AK19: 631492
B20: Danske Bank A/S, Suomen sivuliike | C20: Danske Bank A/S, Suomen sivuliike | D20: HELSINKI | E20: Finland | G20: Active | I20: 41787.614 | K20: 221482 | M20: 381110 | N20: =VLOOKUP(M20,'Spend Export'!$B:$E,4,FALSE) -> 1139926.1 | P20: FI10786932 | R20: No | S20: Yes | T20: Indirect procurement iPRO, Professional services, Business consulting;Indirect procurement iPRO, Taxes and charges, Other regulatory charges | U20: Indirect procurement iPRO, Professional services, Business consulting | V20: Kivimäki Tuomas | W20: tuomas.kivimaki@danskebank.com | X20: Net 14 days | AG20: Aalto Janne;Savolainen Olli | AI20: 2024-05-30 FC - Infor M3 (FC) (FC), Valmet FC Finland Oy 310, Indirect procurement iPRO, Taxes and charges, Other regulatory charges accepted by Mäkelä Henri | AK20: 381110
A21: PriceWaterhouseCoopers LLP | B21: PricewaterhouseCoopers Oy | C21: PricewaterhouseCoopers Oy | D21: HELSINKI | E21: Finland | F21: laskutus.kyselyt@fi.pwc.com | G21: Active | H21: C3 | I21: 37928.615 | K21: 28516 | L21: 368999884 | M21: 162976 | N21: =VLOOKUP(M21,'Spend Export'!$B:$E,4,FALSE) -> 1114989.2 | P21: FI04864068 | R21: No | S21: Yes | T21: Indirect procurement iPRO, Professional services, Business consulting | U21: Indirect procurement iPRO, Professional services, Business consulting | V21: Puukkoniemi Tiina | W21: Tiina.Puukkoniemi@pwc.com | X21: Net 7 days | Z21: X | AA21: Snedsböl Truls | AK21: 162976
B22: Finitec Oy | C22: Finitec Oy | D22: HELSINKI | E22: Finland | F22: reskontra@finitec.fi | G22: Active | I22: 42135.425 | K22: 230688 | M22: 631160 | N22: =VLOOKUP(M22,'Spend Export'!$B:$E,4,FALSE) -> 984321 | P22: FI24547254 | R22: No | S22: Yes | T22: Indirect procurement iPRO, Professional services, Business consulting;Indirect procurement iPRO, Professional services, R&D services & materials;Services, Automation engineering, Automation engineering | U22: Indirect procurement iPRO, Professional services, Business consulting | V22: Martinsuo Teppo | W22: teppo.martinsuo@finitec.fi | X22: Net 45 days | Z22: X | AE22: Pasanen Hannu | AI22: 2023-02-28 FC - Infor M3 (FC) (FC), Indirect procurement iPRO, Professional services, R&D services & materials accepted by Kiema Miika | AK22: 295650
A23: Biisoni | B23: Biisoni Tampere Oy | C23: Biisoni Tampere Oy | D23: HELSINKI | E23: Finland | G23: Active | H23: C3 | I23: 43178.445 | J23: INACTIVE Vakkuri Jarmo | K23: 285890 | M23: 623840 | N23: =VLOOKUP(M23,'Spend Export'!$B:$E,4,FALSE) -> 949359.13 | P23: FI23981569 | Q23: X | R23: Yes | S23: Yes | T23: Indirect procurement iPRO, Personnel, Leased workforce;Services, Subcontracted production capacity, Workforce of subassemblies or assemblies | U23: Indirect procurement iPRO, Personnel, Leased workforce | V23: Illi Jukka | W23: jukka.illi@biisoni.fi | X23: Net 60 days | Y23: X | Z23: X | AA23: Korpela Tuija | AI23: 2025-01-08 Basware - Basware purchasing (Valmet), Indirect procurement iPRO, Personnel, Leased workforce accepted by Korpela Tuija | AK23: 623840
B24: GoMetan III Oy | C24: GoMetan III Oy | D24: JYVÄSKYLÄ | E24: Finland | F24: jyvaskyla@go-on.fi | G24: Active | I24: 43780.543 | J24: Hämäläinen Seppo J | K24: 292621 | L24: 368667988 | M24: 632993 | N24: =VLOOKUP(M24,'Spend Export'!$B:$E,4,FALSE) -> 786589.18 | P24: FI29893586 | R24: No | S24: Yes | T24: Indirect procurement iPRO, Personnel, Leased workforce | U24: Indirect procurement iPRO, Personnel, Leased workforce | V24: Salminen Kimmo | W24: kimmo.salminen@go-on.fi | X24: Net 60 days | Z24: X | AH24: Korpela Tuija | AI24: 2025-01-08 Basware - Basware purchasing (Valmet), Indirect procurement iPRO, Personnel, Leased workforce accepted by Korpela Tuija | AK24: 632993
B25: Nigel Frank International | C25: Nigel Frank International | D25: NEWCASTLE UPON TYNE | E25: United Kingdom | G25: Active | I25: 44589.568 | J25: Latini Luca | K25: 303792 | M25: 647811 | N25: =VLOOKUP(M25,'Spend Export'!$B:$E,4,FALSE) -> #N/A | P25: GB164369978 | R25: No | S25: Yes | T25: Indirect procurement iPRO, Office IT, IT consulting;Indirect procurement iPRO, Professional services, Business consulting | U25: Indirect procurement iPRO, Office IT, IT consulting | V25: Nevin Matthew | W25: m.nevin@nigelfrank.com | X25: Net 30 days | AI25: 2022-02-03 1001 - Infor LN (COF) (Valmet), Indirect procurement iPRO, Professional services, Business consulting accepted by Mäkelä Henri | AK25: 647811
B26: Berggren Oy | C26: Berggren Oy | D26: HELSINKI | E26: Finland | G26: Active | I26: 42033.593 | K26: 229099 | M26: 384283 | N26: =VLOOKUP(M26,'Spend Export'!$B:$E,4,FALSE) -> 745709.07 | P26: FI26358991 | R26: No | S26: Yes | T26: Indirect procurement iPRO, Professional services, Patent services | U26: Indirect procurement iPRO, Professional services, Patent services | V26: Kantanen Jukka | W26: jukka.kantanen@berggren.fi | X26: Net 60 days | AI26: 2024-08-12 FC - Infor M3 (FC) (FC), Valmet FC Finland Oy 310, Indirect procurement iPRO, Professional services, Patent services accepted by Snedsböl Truls | AK26: 384283
B27: ManpowerGroup Oy | C27: ManpowerGroup Oy | D27: HELSINKI | E27: Finland | G27: Active | I27: 37918.711 | K27: 24042 | L27: 651884397 | M27: 607060 | N27: =VLOOKUP(M27,'Spend Export'!$B:$E,4,FALSE) -> 738534.05 | P27: FI10910323 | Q27: X | R27: Yes | S27: Yes | T27: Indirect procurement iPRO, Personnel, Leased workforce | U27: Indirect procurement iPRO, Personnel, Leased workforce | V27: Karlsson Piia | W27: piia.karlsson@manpowergroup.fi | X27: Net 60 days | Z27: X | AA27: Korpela Tuija | AI27: 2025-01-08 Basware - Basware purchasing (Valmet), Indirect procurement iPRO, Personnel, Leased workforce accepted by Korpela Tuija | AK27: 607060
A28: KPMG International | B28: KPMG Oy Ab | C28: KPMG Oy Ab | D28: HELSINKI | E28: Finland | F28: contact@kpmg.fi | G28: Active | H28: C3 | I28: 37918.683 | K28: 21976 | M28: 600689 | N28: =VLOOKUP(M28,'Spend Export'!$B:$E,4,FALSE) -> 711573.76 | P28: FI18054859 | R28: Yes | S28: Yes | T28: Indirect procurement iPRO, Professional services, Business consulting;Indirect procurement iPRO, Professional services, Certification, standardization & audits;Indirect procurement iPRO, Taxes and charges;Indirect procurement iPRO, Taxes and charges, Taxes;Services, Site management and services, Other expert services at site | U28: Indirect procurement iPRO, Professional services, Business consulting | V28: Tiitta Erkki | W28: erkki.tiitta@kpmg.fi | X28: Net 30 days | Z28: X | AA28: Ruusuvaara Petri | AG28: INACTIVE Mariana Erna | AH28: Burmeister Jari;Snedsböl Truls | AI28: 2020-09-15 368 - Valmet (China) Co., Ltd. (SHA) (PAP), Indirect procurement iPRO, Professional services, Certification, standardization & audits accepted by INACTIVE Su Yanjing | AK28: 600689
B29: Fluentscale Oy | C29: Fluentscale Oy | D29: VANTAA | E29: Finland | G29: Active | I29: 42893.593 | K29: 249278 | M29: 406410 | N29: =VLOOKUP(M29,'Spend Export'!$B:$E,4,FALSE) -> #N/A | P29: FI26042663 | R29: No | S29: Yes | T29: Indirect procurement iPRO, Office IT, IT consulting | U29: Indirect procurement iPRO, Office IT, IT consulting | V29: Seppänen Sami | W29: sami.seppanen@fluentscale.fi | X29: Net 45 days | Z29: X | AG29: Rautiainen Mikko | AK29: 406410
B30: Edward Lynx AB | C30: Edward Lynx AB | D30: STOCKHOLM | E30: Sweden | F30: info@edwardlynx.com | G30: Active | I30: 42795.415 | K30: 247559 | M30: 404521 | N30: =VLOOKUP(M30,'Spend Export'!$B:$E,4,FALSE) -> 692085 | P30: SE556546088701 | Q30: X | R30: No | S30: Yes | T30: Indirect procurement iPRO, Personnel, Training & people development;Indirect procurement iPRO, Professional services, Other business services | U30: Indirect procurement iPRO, Personnel, Training & people development | V30: Wretling Ola | W30: ola.wretling@edwardlynx.com | X30: Net 60 days | Y30: X | Z30: X | AH30: Korpela Tuija | AI30: 2023-08-14 FC - Infor M3 (FC) (FC), Indirect procurement iPRO, Personnel, Training & people development accepted by Mäkelä Henri | AK30: 404521
B31: Saltire Projects Limited | C31: Saltire Projects Limited | D31: ABERDEEN | E31: United Kingdom | F31: enquiries@saltireprojects.co.uk | G31: Active | I31: 40218.454 | K31: 148491 | M31: 291824 | N31: =VLOOKUP(M31,'Spend Export'!$B:$E,4,FALSE) -> 605687.1 | P31: GB239300719 | R31: Yes | S31: Yes | T31: Indirect procurement iPRO, Professional services, Business consulting;Indirect procurement iPRO, Professional services, Legal services | U31: Indirect procurement iPRO, Professional services, Business consulting | V31: Adams Keith | W31: keithadams@saltireprojects.co.uk | X31: Net 30 days | Z31: X | AG31: Takala Arto | AI31: 2021-04-16 634 - Valmet Technologies, Inc FIB Pori (MP) (P&E), Indirect procurement iPRO, Professional services, Legal services accepted by Mäkelä Henri | AK31: 291824
B32: Nixu Oy | C32: Nixu Oy | D32: ESPOO | E32: Finland | G32: Active | I32: 40490.605 | K32: 163890 | M32: 309965 | N32: =VLOOKUP(M32,'Spend Export'!$B:$E,4,FALSE) -> #N/A | P32: FI07218117 | Q32: X | R32: No | S32: Yes | T32: Indirect procurement iPRO, Office IT, Software licenses, IT consulting | U32: Indirect procurement iPRO, Office IT, Software licenses, IT consulting | V32: Relander Veera | W32: veera.relander@dnv.com | X32: Net 45 days | Y32: X | Z32: X | AA32: Majaharju Matias;Tapiola Mika;Liukkonen Marko | AK32: 309965
B33: Zure Oy | C33: Zure Oy | D33: HELSINKI | E33: Finland | G33: Active | I33: 43752.511 | J33: INACTIVE Rantalainen Lasse | K33: 292910 | L33: 539828695 | M33: 632449 | N33: =VLOOKUP(M33,'Spend Export'!$B:$E,4,FALSE) -> #N/A | P33: FI24161239 | R33: Yes | S33: Yes | T33: Indirect procurement iPRO, Office IT, IT consulting | U33: Indirect procurement iPRO, Office IT, IT consulting | V33: Nahi Sakari | W33: sakari.nahi@zure.com | X33: Net 45 days | Z33: X | AA33: Tapiola Mika;Liukkonen Marko | AE33: Pasanen Hannu | AI33: 2024-11-28 Basware - Basware purchasing (Valmet), Indirect procurement iPRO, Office IT, IT consulting accepted by Tapiola Mika | AK33: 632449
B34: itdesign GmbH | C34: itdesign GmbH | D34: TUEBINGEN | E34: Germany | G34: Active | I34: 44232.379 | J34: Toropainen Anita | K34: 298858 | M34: 640953 | N34: =VLOOKUP(M34,'Spend Export'!$B:$E,4,FALSE) -> #N/A | P34: DE203913579 | R34: Yes | S34: Yes | T34: Indirect procurement iPRO, Office IT, IT consulting | U34: Indirect procurement iPRO, Office IT, IT consulting | V34: Hartwich Bianca | W34: bianca.hartwich@itdesign.de | X34: Net 45 days | Y34: X | Z34: X | AA34: Liukkonen Marko | AI34: 2021-02-15 1001 - Infor LN (PAP), Indirect procurement iPRO, Office IT, IT consulting (Main category) accepted by Tapiola Mika | AK34: 640953
B35: ManTec AB | C35: ManTec AB | D35: GOTHENBURG | E35: Sweden | F35: mantec@mantec.eu | G35: Active | I35: 45055.706 | J35: Olsson Åke | K35: 316166 | M35: 663937 | N35: =VLOOKUP(M35,'Spend Export'!$B:$E,4,FALSE) -> 522745 | P35: SE556717793501 | R35: No | S35: Yes | T35: Indirect procurement iPRO, Professional services, Business consulting | U35: Indirect procurement iPRO, Professional services, Business consulting | V35: Johannission Håkan | W35: hakan.johannisson@mantec.eu | X35: Net 60 days | AI35: 2023-07-07 642 - SER (SWE) (SER), Indirect procurement iPRO, Professional services, Business consulting (Main category) accepted by Snedsböl Truls | AK35: 663937
A36: Digia | B36: Digia Finland Oy | C36: Digia Finland Oy | D36: HELSINKI | E36: Finland | F36: digia.finland@bscs.basware.com | G36: Active | H36: C3 | I36: 38569.687 | K36: 87697 | M36: 218764 | N36: =VLOOKUP(M36,'Spend Export'!$B:$E,4,FALSE) -> #N/A | P36: FI10912484 | R36: No | S36: Yes | T36: Indirect procurement iPRO, Office IT, Application management;Indirect procurement iPRO, Office IT, IT consulting | U36: Indirect procurement iPRO, Office IT, IT consulting | V36: Tumanoff Tommi | W36: tommi.tumanoff@digia.com | X36: Net 30 days | Z36: X | AA36: Tapiola Mika;Liukkonen Marko | AK36: 218764
B37: Sweden Modular Management AB | C37: Sweden Modular Management AB | D37: STOCKHOLM | E37: Sweden | F37: info@modularmanagement.com | G37: Active | I37: 41954.494 | K37: 228153 | M37: 383188 | N37: =VLOOKUP(M37,'Spend Export'!$B:$E,4,FALSE) -> 478302.71 | P37: SE556982984801 | R37: Yes | S37: Yes | T37: Indirect procurement iPRO, Professional services, R&D services & materials | U37: Indirect procurement iPRO, Professional services, R&D services & materials | V37: Berggren Peter | W37: peter.berggren@modularmanagement.com | X37: Net 45 days | Z37: X | AH37: Snedsböl Truls | AK37: 383188
B38: Rekrytointipalvelu Sihti Oy | C38: Rekrytointipalvelu Sihti Oy | D38: TAMPERE | E38: Finland | F38: laskutus@sihti.fi | G38: Active | I38: 42199.436 | K38: 231530 | L38: 651294964 | M38: 386990 | N38: =VLOOKUP(M38,'Spend Export'!$B:$E,4,FALSE) -> 453472.05 | P38: FI22425579 | R38: No | S38: Yes | T38: Indirect procurement iPRO, Personnel, Leased workforce | U38: Indirect procurement iPRO, Personnel, Leased workforce | V38: Lindgren Joni | W38: joni.lindgren@sihti.fi | X38: Net 60 days | Y38: X | AG38: Kuru Antti | AI38: 2024-11-05 Basware - Basware purchasing (Valmet), Indirect procurement iPRO, Personnel, Leased workforce accepted by Korpela Tuija | AK38: 386990
B39: Taitopilvi Oy | C39: Taitopilvi Oy | D39: JYVÄSKYLÄ | E39: Finland | G39: Active | I39: 43005.65 | J39: Majaharju Matias | K39: 284255 | M39: 621542 | N39: =VLOOKUP(M39,'Spend Export'!$B:$E,4,FALSE) -> #N/A | P39: FI27861337 | R39: No | S39: Yes | T39: Indirect procurement iPRO, Office IT, Application management, IT consulting;Indirect procurement iPRO, Professional services, Other business services | U39: Indirect procurement iPRO, Office IT, Application management, IT consulting | V39: Heinola Matti | W39: matti.heinola@taitopilvi.fi | X39: Net 30 days | Z39: X | AA39: Tapiola Mika;Liukkonen Marko;Majaharju Matias | AI39: 2017-11-01 639 - Valmet Technologies, Inc PPP HO (MP) (Valmet), Indirect procurement iPRO, Professional services, Other business services accepted by Mäkelä Henri | AK39: 621542
B40: Melkki Partners Oy | C40: Melkki Partners Oy | D40: HELSINKI | E40: Finland | G40: Active | I40: 44749.439 | J40: Liukkonen Marko | K40: 306128 | M40: 650578 | N40: =VLOOKUP(M40,'Spend Export'!$B:$E,4,FALSE) -> #N/A | P40: FI32049917 | R40: No | S40: Yes | T40: Indirect procurement iPRO, Office IT, IT consulting | U40: Indirect procurement iPRO, Office IT, IT consulting | V40: Felixson Patrik | W40: patrik.felixson@melkki.fi | X40: Net 45 days | Z40: X | AA40: Liukkonen Marko;Tapiola Mika | AI40: 2022-08-15 1001 - Infor LN (COF) (Valmet), Indirect procurement iPRO, Office IT, IT consulting (Main category) accepted by Tapiola Mika | AK40: 650578
...

Sheet FI_dataPOCcleaned
A1: This sheet has illustrative detail on Training category suppliers that has been collected by category manager but is not available in supplier master fully
A3: Business Partner Company Name | B3: Supplier code | C3: Training supplier Y/N | D3: EXAMPLES: Pricing / day / trainer EUR (if no data: average based on invoicing) | E3: Country | F3: Delivery country | G3: Contract available at the moment | H3: Classification | I3: Nature of the service | J3: Training area | K3: HSE training provider | L3: Valmet contact person (CoMPass) | M3: Catalog in Basware Shop | N3: Preferred supplier in CoMPass (Mikko)
A4: IMD-International Institute for Managem. Develop. | B4: 383390 | C4: Y | D4: no detailed info | E4: Finland | F4: Global | G4: Y | H4: A | I4: Global training programs | J4: Global training programs / Forward | L4: Tuija Korpela, Hanna Heikkilä | M4: y
A5: Aalto University Executive Education Oy | B5: 615149 | C5: Y | D5: no detailed info | E5: Finland | F5: Global | G5: Y | H5: A | I5: Leadership, management and team development | J5: World Class Supply chain, Global leader, First time manager, CSRD & sustainability reporting, MBA | L5: Tuija Korpela, Riikka Happonen | M5: y
A6: AS3 Finland Oy | B6: 403389 | C6: Y | D6: 3000 | E6: Finland | F6: Global | G6: Y | H6: A | I6: Coaching and work counseling | J6: Group coaching new managers, coaching, manager as career coach training | L6: Tuija Korpela | M6: y | N6: Yes
A7: Hanken & SSE Executive Education Ab | B7: 288703 | C7: Y | D7: no detailed info | E7: Finland | F7: Global | G7: Y | H7: A | I7: Leadership, management and team development | J7: Hanken EMBA programme fees | L7: Jussi Mäntyniemi | M7: y
A8: IMPLEMENT CONSULTING GROUP P/S | B8: 391772 | C8: Y | D8: no detailed info | E8: Finland | F8: Global | G8: Y | H8: A | I8: HSE, quality and work wellbeing | J8: Leading through lean | K8: x | L8: Meri-Tuuli Sipari | M8: y
A9: Bitville Oy | B9: 400676 | C9: Y | D9: no detailed info | E9: Finland | G9: N | H9: A
A10: Resilio Oy | B10: 407540 | C10: Y | D10: 2000 | E10: Finland | F10: Finland / EMEA | G10: Y | H10: A | I10: HSE, quality and work wellbeing +J7:J10 | J10: Work psychologist services most part, Manager guidance | K10: x | L10: Tuija Korpela, Anne Onkila | M10: y | N10: Yes
A11: Peili Consulting Oy | B11: 386353 | C11: Y | D11: 2000 | E11: Finland | F11: Global | G11: Y | H11: A | I11: Interaction/ presentation/ communication/ influencing | J11: Peili -trainings | L11: Reijo Heinämäki | M11: y | N11: Yes
A12: Hope Consulting Oy | B12: 389324 | C12: Y | D12: 2500 | E12: Finland | F12: Finland | G12: Y | H12: A | I12: Coaching and work counseling | J12: Work counselling of a new manager | L12: Tuija Korpela, Eero Halmari | M12: y | N12: Yes
A13: Medwick V. Byrd Jr. | B13: 601076 | C13: Y | D13: 1200 | E13: Finland | F13: Global | G13: Y | H13: A | I13: Product, service or technology trainings | J13: Valmet Process Technology School training | L13: Reijo Heinämäki | M13: y
A14: Pal Lokendra | B14: 622308 | C14: Y | D14: 1200 | E14: Finland | F14: Global | G14: Y | H14: A | I14: Product, service or technology trainings | J14: Valmet Process Technology School | L14: Reijo Heinämäki | M14: y
A15: EF Corporate Education Ltd | B15: 665822 | C15: Y | D15: no detailed info | E15: Finland | G15: Y | H15: A | I15: Business culture and language training | J15: language training | L15: Jutta Rouru | M15: y
A16: International Institute for Learning Finland Oy | B16: 295648 | C16: Y | D16: 2500 | E16: Finland | F16: Global | G16: Y | H16: A | I16: Leadership, management and team development, project management | J16: PMIQ, Agile & scrum, PMI Authorized PMP | L16: Eero Halmari | M16: y
A17: Hasan Jameel | B17: 601536 | C17: Y | D17: 1300 | E17: Finland | F17: Global | G17: Y | H17: A | I17: Product, service or technology trainings | J17: Valmet Process Technology School training | L17: Reijo Heinämäki | M17: y
A18: Verona Consulting Oy | B18: 606814 | C18: Y | D18: no detailed info | E18: Finland | F18: Global | G18: Y | H18: A | I18: Global training programs | J18: Champions in Services | L18: Riikka Happonen | M18: y
A19: Board of Innovation BVBA | B19: 406951 | C19: Y | D19: no detailed info | E19: Finland | F19: Global | G19: Y | H19: A | I19: Global training programs | J19: Enhanced IP 2023 project | L19: Riikka Happonen | M19: y
A20: Hyvinvoinnin Suurlähettiläät Oy | B20: 635292 | C20: Y | D20: 4000 | E20: Finland | F20: EMEA | G20: Y | H20: A | I20: Leadership, management and team development | J20: Training site leaders, co-operation development process, leadership team development process 360, Coaching training for managers | L20: Eero Halmari
A21: Anna-Mari Laulumaa Oy | B21: 240448 | C21: Y | E21: Finland | G21: N | H21: B | I21: Business culture and language training | J21: Interaction training | L21: Tuomo Linnaranta
A22: Sinkkonen Consulting Oy | B22: 349102 | C22: Y | E22: Finland | F22: EMEA | G22: Y | H22: B | I22: Business culture and language training | J22: Global moblity related trainings, for expatriates etc, | L22: Riikka Hermunen
A23: AEL-Amiedu Oy | B23: 634973 | C23: Y | E23: Finland | F23: Finland | G23: N | H23: B | I23: Product, service or technology trainings | J23: Technical training | L23: Jyri Palmu
A24: Helsingin Kamari Oy | B24: 509013 | C24: Y | E24: Finland | F24: Finland | G24: Under negotiation | H24: B | I24: Various/other skills | J24: User licenses and brand visibility, few export trainings, Koulutus-Online platform | L24: Ari Leppäniemi
A25: Saranen Consulting Oy | B25: 389430 | C25: Y | E25: Finland | F25: Finland | G25: N | H25: B | I25: Product, service or technology trainings | J25: Participation in training program: Industry 4.0 and automation; Outplacement services | L25: Petra Miesmaa
A26: Tampere Business Campus TBC ry | B26: 224445 | C26: Y | E26: Finland | F26: Finland | G26: N | H26: B | I26: Various/other skills | J26: TBC licence, fees for late cancellation of event participation | L26: Jenni Siivonen
A27: Jyväskylän Ammattikorkeakoulu | B27: 201515 | C27: Y | E27: Finland | F27: Finland | G27: Y | H27: B | I27: Various/other skills | J27: E-learning services, Co-operation agreement 3 years finance and business law students, Equiqment calibration, another co-operation agreement with student union | L27: Reijo Heinämäki
A28: Apprix Oy | B28: 239755 | C28: Y | E28: Finland | F28: Finland | G28: Y | H28: B | I28: Elearnings and digital learning solutions | J28: Builder user license monthly, project work related to e-learning courses | L28: Meri-Tuuli Sipari
A29: Psykologipalvelut Hippu Pintilä | B29: 635240 | C29: Y | E29: Finland | F29: Finland | G29: N | H29: B | I29: Leadership, management and team development; HSE, quality and work wellbeing | J29: Management team development, work guidance for managers, team development, Discovery insights , workshops | K29: x | L29: Eero Halmari
A30: North Carolina State University | B30: 601852 | C30: Y | E30: Finland | F30: Global | G30: Y | H30: B | I30: Product, service or technology trainings | J30: Can't access information | L30: Niklas Nylund
A31: Jyväskylän Yliopisto | B31: 224515 | C31: Y | E31: Finland | F31: Finland / Global | G31: N | H31: B | I31: Various/other skills | J31: Printing costs for masters thesis | L31: Miia Lompolo
A32: Rokmind Oy | B32: 647801 | C32: Y | E32: Finland | F32: Finland | G32: N | H32: B | I32: Leadership, management and team development | J32: Services: Insight Profiles for IT Leap (Team development assessments) | L32: Eero Halmari
A33: Nordic Business Forum Oy | B33: 657108 | C33: N | E33: Finland | F33: Global | G33: N | H33: B | I33: Leadership, management and team development | J33: NBF Remote license | L33: Mika Tapiola
A34: Kaakkois-Suomen Ammattikorkeakoulu Oy | B34: 623267 | C34: Y | E34: Finland | G34: N | H34: B | I34: Various/other skills | J34: NextGenMix-project | L34: Reijo Pietikäinen
A35: Oy Speakers Forum Finland Ab | B35: 331659 | C35: N | E35: Finland | G35: N | H35: B | I35: HSE, quality and work wellbeing | J35: Karri Kivi, tyhy-speaker | K35: x | L35: Eero Halmari
A36: Itä-Suomen Yliopisto | B36: 291786 | E36: Finland | G36: N | H36: B | I36: Various/other skills | J36: SUSBINCO project | L36: Annika Ahlfors
A37: Kajaanin Ammattikorkeakoulu Oy | B37: 386089 | C37: Y | E37: Finland | F37: Finland | G37: N | H37: B | I37: Product, service or technology trainings | J37: Metsästä energiaksi - MENER project funding 2023, EMC-testing | L37: Susanna Glad
A38: Stichting Gasturbine Onderwijs | B38: 644372 | E38: Finland | G38: N | H38: B | I38: Product, service or technology trainings | J38: Turbomachinery course | L38: Sylvia Malenstein
A39: HAK Nova Oy | B39: 630977 | C39: Y | D39: 3000 | E39: Finland | F39: EMEA | G39: Y | H39: B | I39: Coaching and work counseling | J39: coaching | L39: Leila Figueiredo => Eero Halmari
A40: Imaction | B40: 646544 | C40: Y | E40: Finland | G40: N | H40: B | I40: Leadership, management and team development | J40: Forward through change training; https://www.imaction.fi/ | L40: Mari Poikonen
A41: Eeva Niskavaara Consulting Oy | B41: 402182 | C41: Y | E41: Finland | F41: Finland | G41: N | H41: B | I41: Interaction/ presentation/ communication/ influencing | J41: Finance trainings | L41: Bill Zervas => Reijo Heinämäki
...
